Begin test suite
  test cases being run: 1
  Begin test case
    test case name: "exception_assertion"
    file: "exception_assertion.test.cpp"
    line: 5
    Begin test case run
      Begin section
        sections: good std::exception
      Begin assertion
        expression: myFunction()
        line: 11
      End assertion
        assertion success: true
        Throw assertion
          expected exception: std::exception
          exception thrown: true
          exception message: my error
      End section
        sections: good std::exception
        section success: true
    End test case run
      test assertions ran: 1
      test assertions passed: 1
      test assertions failed: 0
      test case run success: true
    Begin test case run
      Begin section
        sections: good std::runtime_error
      Begin assertion
        expression: myFunction()
        line: 18
      End assertion
        assertion success: true
        Throw assertion
          expected exception: std::runtime_error
          exception thrown: true
          exception message: my error
      End section
        sections: good std::runtime_error
        section success: true
    End test case run
      test assertions ran: 1
      test assertions passed: 1
      test assertions failed: 0
      test case run success: true
    Begin test case run
      Begin section
        sections: bad std::logic_error
      Begin assertion
        expression: myFunction()
        line: 25
      End assertion
        assertion success: false
        Throw assertion
          expected exception: std::runtime_error
          exception thrown: true
          exception message: my error
      End section
        sections: bad std::logic_error
        section success: false
    End test case run
      test assertions ran: 1
      test assertions passed: 0
      test assertions failed: 1
      test case run success: false
      exception type: class std::exception
      exception message: "my error"
    Begin test case run
      Begin section
        sections: bad no throw
      Begin assertion
        expression: myFunction()
        line: 32
      End assertion
        assertion success: false
        Throw assertion
          expected exception: std::runtime_error
          exception thrown: false
          exception message: 
      End section
        sections: bad no throw
        section success: false
    End test case run
      test assertions ran: 1
      test assertions passed: 0
      test assertions failed: 1
      test case run success: false
      exception type: class std::runtime_error
      exception message: "Assertion failed"
    Begin test case run
    End test case run
      test assertions ran: 0
      test assertions passed: 0
      test assertions failed: 0
      test case run success: true
  End test case
    test assertions ran: 4
    test assertions passed: 2
    test assertions failed: 2
    test case success: false
End test suite
  test cases ran: 1
  test cases passed: 0
  test cases failed: 1
  test assertions ran: 4
  test assertions passed: 2
  test assertions failed: 2
  test suite success: false
